Workbook
Name Slicer_City_Clean: #N/A
Name Slicer_Industry_Category: #N/A
Name Slicer_Year: #N/A

Sheet Raw Data
A1: Sr No | B1: Date dd/mm/yyyy | C1: Startup Name | D1: Industry Vertical | E1: SubVertical | F1: City Location | G1: Investors Name | H1: InvestmentnType | I1: Amount in USD | J1: Remarks
A2: 1 | B2: 43839 | C2: BYJU’S | D2: E-Tech | E2: E-learning | F2: Bengaluru | G2: Tiger Global Management | H2: Private Equity Round | I2: 200000000
A3: 2 | B3: 43843 | C3: Shuttl | D3: Transportation | E3: App based shuttle service | F3: Gurgaon | G3: Susquehanna Growth Equity | H3: Series C | I3: 8048394
A4: 3 | B4: 43839 | C4: Mamaearth | D4: E-commerce | E4: Retailer of baby and toddler products | F4: Bengaluru | G4: Sequoia Capital India | H4: Series B | I4: 18358860
A5: 4 | B5: 43832 | C5: https://www.wealthbucket.in/ | D5: FinTech | E5: Online Investment | F5: New Delhi | G5: Vinod Khatumal | H5: Pre-series A | I5: 3000000
A6: 5 | B6: 43832 | C6: Fashor | D6: Fashion and Apparel | E6: Embroiled Clothes For Women | F6: Mumbai | G6: Sprout Venture Partners | H6: Seed Round | I6: 1800000
A7: 6 | B7: 43843 | C7: Pando | D7: Logistics | E7: Open-market, freight management platform | F7: Chennai | G7: Chiratae Ventures | H7: Series A | I7: 9000000
A8: 7 | B8: 43840 | C8: Zomato | D8: Hospitality | E8: Online Food Delivery Platform | F8: Gurgaon | G8: Ant Financial | H8: Private Equity Round | I8: 150000000
A9: 8 | B9: 43811 | C9: Ecozen | D9: Technology | E9: Agritech | F9: Pune | G9: Sathguru Catalyzer Advisors | H9: Series A | I9: 6000000
A10: 9 | B10: 43805 | C10: CarDekho | D10: E-Commerce | E10: Automobile | F10: Gurgaon | G10: Ping An Global Voyager Fund | H10: Series D | I10: 70000000
A11: 10 | B11: 43802 | C11: Dhruva Space | D11: Aerospace | E11: Satellite Communication | F11: Bengaluru | G11: Mumbai Angels, Ravikanth Reddy | H11: Seed | I11: 50000000
A12: 11 | B12: 43812 | C12: Rivigo | D12: Technology | E12: Logistics Services and Solutions | F12: Gurgaon | G12: SAIF Partners, Spring Canter Investment Ltd. | H12: Series F | I12: 20000000
A13: 12 | B13: 43816 | C13: Healthians | D13: B2B-focused foodtech startup | E13: Food Solutions For Corporate | F13: Bengaluru | G13: Paytm, NPTK, Sabre Partners and Neoplux | H13: Series C | I13: 12000000
A14: 13 | B14: 43815 | C14: Licious | D14: E-Commerce | E14: Online Meat And Seafood Ordering Startup | F14: Bengaluru | G14: Vertex Growth Fund | H14: Series E | I14: 30000000
A15: 14 | B15: 43815 | C15: InCred | D15: Finance | E15: Non-Banking Financial Company | F15: Mumbai | H15: Debt Funding | I15: 5900000
A16: 15 | B16: 43813 | C16: Trell | D16: Video | E16: Experience Discovery Platform | F16: Bengaluru | G16: Ruizheng Investment | H16: Seed Round | I16: 2000000
A17: 16 | B17: 43810 | C17: Rein Games | D17: Gaming | E17: Real money based gaming startup | F17: Noida | G17: Manipal Education and Medical Group (MEMG) | H17: Seed Round | I17: 50000000
A18: 17 | B18: 43819 | C18: Lenskart.com | D18: E-Commerce | E18: Online Eyewear Shopping Portal | F18: Faridabad | G18: SoftBank Vision Fund | H18: Series G | I18: 231000000
A19: 18 | B19: 43782 | C19: Freshworks | D19: Software | E19: Business and customer engagement tools | F19: San Francisco | G19: Sequoia, CapitalG, Accel | H19: Series H | I19: 150000000
A20: 19 | B20: 43783 | C20: Misters | D20: Health and wellness | E20: Men's Health and Wellness brand | F20: Gurgaon | G20: Sauce.vc, Rainforest Ventures | H20: Series B | I20: 486000
A21: 20 | B21: 43782 | C21: Sunstone Eduversity Pvt. Ltd | D21: Education | E21: Elearning | F21: Gurgaon | G21: Prime Venture Partners, LetsVenture, PS1 Venture and GlobalLogic co-founder Rajul Garg | H21: Seed | I21: 1500000
A22: 21 | B22: 43786 | C22: Burger Singh | D22: Food and Beverage | E22: Indian Burger Brand | F22: Gurgaon | G22: RB Investments | H22: Venture | I22: undisclosed
A23: 22 | B23: 43787 | C23: Healthians | D23: Health and Wellness | E23: Healthcare services | F23: Gurgaon | G23: DG Daiwa Ventures, DG Incubation | H23: Series B | I23: 12000000
A24: 23 | B24: 43784 | C24: Ninjacart | D24: B2B Marketing | E24: Agritech | F24: Bengaluru | G24: Trifecta Capital Advisors | H24: Debt Funding | I24: 26000000
A25: 24 | B25: 43789 | C25: Aye Finance | D25: FinTech | E25: Financial Services To MSMEs | F25: Gurgaon | G25: FinTech | H25: Debt Funding | I25: 17411265
A26: 25 | B26: 43781 | C26: SuperGaming | D26: Video Games | E26: Social gaming platform | F26: Pune | G26: Dream Incubator | H26: Seed Funding | I26: 1300000
A27: 26 | B27: 43789 | C27: Clumio | D27: SaaS | E27: Recovery software | F27: San Jose, | G27: Altimeter Capital, Sutter Hill Ventures | H27: Series C | I27: 135000000
A28: 27 | B28: 43780 | C28: eBikeGo | D28: Last Mile Transportation | E28: Electric bike rental | F28: Amritsar | G28: Startup Buddy | H28: Seed | I28: 300000
A29: 28 | B29: 43788 | C29: Digital Mall Asia | D29: E-Commerce | E29: Virtual e-commerce platform | F29: Delhi | G29: Amour Infrastructure | H29: Seed Funding | I29: 220000000
A30: 29 | B30: 43787 | C30: Medikabazaar | D30: Healthcare | E30: B2B platform for medical supplies | F30: Mumbai | G30: Ackermans & van Haaren, HealthQuad, Rebright Partners, Toppan Printing | H30: Series B | I30: 15800000
A31: 30 | B31: 43784 | C31: Vogo Automotive | D31: Last Mile Transportation | E31: Scooter sharing app | F31: Kormangala | G31: Matrix Partners, Stellaris Venture Partners, Kalaari Capital | H31: Series B | I31: 283000000
A32: 31 | B32: 43788 | C32: Furtados School of Music | D32: Education | E32: Music Education | F32: Tulangan | G32: IAN Fund and DSG Consumer Partners | I32: 200000000
A33: 32 | B33: 43794 | C33: Paytm | D33: FinTech | E33: Mobile Wallet | F33: Noida | G33: Vijay Shekhar Sharma | H33: Funding Round | I33: 1000000000
A34: 33 | B34: 43742 | C34: Dunzo | D34: Customer Service | E34: Delivery Service | F34: Bengaluru | G34: Lightbox | H34: Series D | I34: 45000000
A35: 34 | B35: 43740 | C35: Udaan | D35: B2B | E35: Business development | F35: Bengaluru | G35: Altimeter Capital, DST Global | H35: Series D | I35: 585000000
A36: 35 | B36: 43759 | C36: The Man Company | D36: Consumer Goods | E36: Beauty and Grooming | F36: Gurgaon | G36: Ayushmann Khurana | H36: Corporate Round | I36: unknown
A37: 36 | B37: 43713 | C37: FPL Technologies | D37: FinTech | E37: Financial Services | F37: Pune | G37: Matrix Partners India, Sequoia India | H37: Maiden Round | I37: 4500000
A38: 37 | B38: 43712 | C38: Cashflo | D38: FinTech | E38: Invoice discounting platform and SME lending marketplace | F38: Mumbai | G38: SAIF Partners | H38: Series A | I38: 3300000
A39: 38 | B39: 43712 | C39: Digital F5 | D39: Advertising, Marketing | E39: Digital marketing firm | F39: Mumbai | G39: TIW Private Equity | H39: Private Equity Round | I39: 6000000
A40: 39 | B40: 43712 | C40: 3rdFlix | D40: SaaS | E40: Education Technology | F40: Hyderabad | G40: Exfinity Venture Partners | H40: pre-series A | I40: 5000000
...

Sheet Cleaned Data
A1: Sr No | B1: Date | C1: Startup Name | D1: Industry | E1: Sub Industry | F1: City | G1: Investors | H1: Primary Investor | I1: Investor Count | J1: Multiple Investors | K1: Investment Type | L1: Amount USD | M1: Year | N1: Month | O1: Amount Crore INR | P1: Funding Stage Clean | Q1: Industry Category | R1: City Clean
A2: 1 | B2: 43839 | C2: BYJU’S | D2: E-Tech | E2: E-learning | F2: Bengaluru | G2: Tiger Global Management | H2: =IFERROR(TRIM(LEFT(G2,FIND(",",G2)-1)),TRIM(G2)) -> Tiger Global Management | I2: =IF(TRIM(G2)="",0,LEN(G2)-LEN(SUBSTITUTE(G2,",",""))+1) -> 1 | J2: =IF(Table1[[#This Row],[Investor Count]]>1,"Yes","No") -> No | K2: Private Equity Round | L2: 200000000 | M2: =YEAR(B2) -> 2020 | N2: =TEXT(B2,"mmmm") -> January | O2: 1919.41 | P2: =IF(ISBLANK(K2),"Unknown",IF(OR(ISNUMBER(SEARCH("seed",K2)),ISNUMBER(SEARCH("Seed",K2))),"Seed",IF(ISNUMBER(SEARCH("Series A",K2)),"Series A",IF(ISNUMBER(SEARCH("Series B",K2)),"Series B",IF(ISNUMBER(SEARCH("Series C",K2)),"Series C",IF(ISNUMBER(SEARCH("Series D",K2)),"Series D",IF(ISNUMBER(SEARCH("Private Equity",K2)),"Private Equity","Other"))))))) -> Private Equity | Q2: =IF(IFERROR(SEARCH("ecom",D2),0)+IFERROR(SEARCH("commerce",D2),0)+IFERROR(SEARCH("retail",D2),0)>0,"E-Commerce", IF(IFERROR(SEARCH("fintech",D2),0)+IFERROR(SEARCH("finance",D2),0)+IFERROR(SEARCH("financial",D2),0)+IFERROR(SEARCH("lending",D2),0)+IFERROR(SEARCH("payment",D2),0)+IFERROR(SEARCH("banking",D2),0)+IFERROR(SEARCH("insurance",D2),0)>0,"FinTech", IF(IFERROR(SEARCH("tech",D2),0)+IFERROR(SEARCH("software",D2),0)+IFERROR(SEARCH("saas",D2),0)+IFERROR(SEARCH("ai",D2),0)+IFERROR(SEARCH("iot",D2),0)+IFERROR(SEARCH("cloud",D2),0)+IFERROR(SEARCH("data",D2),0)+IFERROR(SEARCH("analytics",D2),0)>0,"Technology", IF(IFERROR(SEARCH("food",D2),0)+IFERROR(SEARCH("restaurant",D2),0)+IFERROR(SEARCH("hospitality",D2),0)+IFERROR(SEARCH("beverage",D2),0)+IFERROR(SEARCH("delivery",D2),0)>0,"Food & Beverage", IF(IFERROR(SEARCH("health",D2),0)+IFERROR(SEARCH("medical",D2),0)+IFERROR(SEARCH("pharma",D2),0)+IFERROR(SEARCH("wellness",D2),0)+IFERROR(SEARCH("fitness",D2),0)>0,"Healthcare", IF(IFERROR(SEARCH("edu",D2),0)+IFERROR(SEARCH("learning",D2),0)+IFERROR(SEARCH("school",D2),0)+IFERROR(SEARCH("e-tech",D2),0)>0,"Education", IF(IFERROR(SEARCH("logistics",D2),0)+IFERROR(SEARCH("transport",D2),0)+IFERROR(SEARCH("delivery",D2),0)+IFERROR(SEARCH("mobility",D2),0)+IFERROR(SEARCH("automobile",D2),0)>0,"Logistics & Transport", IF(IFERROR(SEARCH("travel",D2),0)+IFERROR(SEARCH("hotel",D2),0)+IFERROR(SEARCH("booking",D2),0)+IFERROR(SEARCH("tourism",D2),0)>0,"Travel & Hospitality", IF(IFERROR(SEARCH("fashion",D2),0)+IFERROR(SEARCH("apparel",D2),0)+IFERROR(SEARCH("clothing",D2),0)+IFERROR(SEARCH("jewelry",D2),0)+IFERROR(SEARCH("beauty",D2),0)>0,"Fashion & Lifestyle", IF(IFERROR(SEARCH("media",D2),0)+IFERROR(SEARCH("entertainment",D2),0)+IFERROR(SEARCH("video",D2),0)+IFERROR(SEARCH("gaming",D2),0)+IFERROR(SEARCH("music",D2),0)+IFERROR(SEARCH("social",D2),0)>0,"Media & Entertainment", IF(IFERROR(SEARCH("agri",D2),0)+IFERROR(SEARCH("farm",D2),0)+IFERROR(SEARCH("agtech",D2),0)>0,"Agriculture", IF(IFERROR(SEARCH("real estate",D2),0)+IFERROR(SEARCH("property",D2),0)+IFERROR(SEARCH("housing",D2),0)>0,"Real Estate", IF(IFERROR(SEARCH("energy",D2),0)+IFERROR(SEARCH("solar",D2),0)+IFERROR(SEARCH("clean tech",D2),0)+IFERROR(SEARCH("waste",D2),0)>0,"Energy & Environment", IF(IFERROR(SEARCH("hr",D2),0)+IFERROR(SEARCH("recruit",D2),0)+IFERROR(SEARCH("hiring",D2),0)+IFERROR(SEARCH("job",D2),0)>0,"HR & Recruitment", "Others")))))))))))))) -> Technology | R2: =IF(ISNUMBER(SEARCH("bang",F2)),"Bangalore",IF(ISNUMBER(SEARCH("beng",F2)),"Bangalore",IF(ISNUMBER(SEARCH("mumbai",F2)),"Mumbai",IF(ISNUMBER(SEARCH("delhi",F2)),"Delhi-NCR",IF(ISNUMBER(SEARCH("gurgaon",F2)),"Delhi-NCR",IF(ISNUMBER(SEARCH("gurugram",F2)),"Delhi-NCR",IF(ISNUMBER(SEARCH("noida",F2)),"Delhi-NCR",IF(ISNUMBER(SEARCH("faridabad",F2)),"Delhi-NCR",IF(ISNUMBER(SEARCH("chennai",F2)),"Chennai",IF(ISNUMBER(SEARCH("hyderabad",F2)),"Hyderabad",IF(ISNUMBER(SEARCH("pune",F2)),"Pune",IF(ISNUMBER(SEARCH("kolkata",F2)),"Kolkata",IF(ISNUMBER(SEARCH("ahmedabad",F2)),"Ahmedabad",IF(ISNUMBER(SEARCH("jaipur",F2)),"Jaipur",IF(ISNUMBER(SEARCH("coimbatore",F2)),"Coimbatore",IF(ISNUMBER(SEARCH("kochi",F2)),"Kerala Cities",IF(ISNUMBER(SEARCH("cochin",F2)),"Kerala Cities",IF(ISNUMBER(SEARCH("francisco",F2)),"USA",IF(ISNUMBER(SEARCH("new york",F2)),"USA",IF(ISNUMBER(SEARCH("california",F2)),"USA",IF(ISNUMBER(SEARCH("palo alto",F2)),"USA",IF(ISNUMBER(SEARCH("santa",F2)),"USA",IF(ISNUMBER(SEARCH("singapore",F2)),"Singapore",IF(ISNUMBER(SEARCH("london",F2)),"London/UK",IF(F2="","Unknown","Other Cities"))))))))))))))))))))))))) -> Bangalore
A3: 2 | B3: 43843 | C3: Shuttl | D3: Transportation | E3: App based shuttle service | F3: Gurgaon | G3: Susquehanna Growth Equity | H3: =IFERROR(TRIM(LEFT(G3,FIND(",",G3)-1)),TRIM(G3)) -> Susquehanna Growth Equity | I3: =IF(TRIM(G3)="",0,LEN(G3)-LEN(SUBSTITUTE(G3,",",""))+1) -> 1 | J3: =IF(Table1[[#This Row],[Investor Count]]>1,"Yes","No") -> No | K3: Series C | L3: 8048394 | M3: =YEAR(B3) -> 2020 | N3: =TEXT(B3,"mmmm") -> January | O3: 77.24084 | P3: =IF(ISBLANK(K3),"Unknown",IF(OR(ISNUMBER(SEARCH("seed",K3)),ISNUMBER(SEARCH("Seed",K3))),"Seed",IF(ISNUMBER(SEARCH("Series A",K3)),"Series A",IF(ISNUMBER(SEARCH("Series B",K3)),"Series B",IF(ISNUMBER(SEARCH("Series C",K3)),"Series C",IF(ISNUMBER(SEARCH("Series D",K3)),"Series D",IF(ISNUMBER(SEARCH("Private Equity",K3)),"Private Equity","Other"))))))) -> Series C | Q3: =IF(IFERROR(SEARCH("ecom",D3),0)+IFERROR(SEARCH("commerce",D3),0)+IFERROR(SEARCH("retail",D3),0)>0,"E-Commerce", IF(IFERROR(SEARCH("fintech",D3),0)+IFERROR(SEARCH("finance",D3),0)+IFERROR(SEARCH("financial",D3),0)+IFERROR(SEARCH("lending",D3),0)+IFERROR(SEARCH("payment",D3),0)+IFERROR(SEARCH("banking",D3),0)+IFERROR(SEARCH("insurance",D3),0)>0,"FinTech", IF(IFERROR(SEARCH("tech",D3),0)+IFERROR(SEARCH("software",D3),0)+IFERROR(SEARCH("saas",D3),0)+IFERROR(SEARCH("ai",D3),0)+IFERROR(SEARCH("iot",D3),0)+IFERROR(SEARCH("cloud",D3),0)+IFERROR(SEARCH("data",D3),0)+IFERROR(SEARCH("analytics",D3),0)>0,"Technology", IF(IFERROR(SEARCH("food",D3),0)+IFERROR(SEARCH("restaurant",D3),0)+IFERROR(SEARCH("hospitality",D3),0)+IFERROR(SEARCH("beverage",D3),0)+IFERROR(SEARCH("delivery",D3),0)>0,"Food & Beverage", IF(IFERROR(SEARCH("health",D3),0)+IFERROR(SEARCH("medical",D3),0)+IFERROR(SEARCH("pharma",D3),0)+IFERROR(SEARCH("wellness",D3),0)+IFERROR(SEARCH("fitness",D3),0)>0,"Healthcare", IF(IFERROR(SEARCH("edu",D3),0)+IFERROR(SEARCH("learning",D3),0)+IFERROR(SEARCH("school",D3),0)+IFERROR(SEARCH("e-tech",D3),0)>0,"Education", IF(IFERROR(SEARCH("logistics",D3),0)+IFERROR(SEARCH("transport",D3),0)+IFERROR(SEARCH("delivery",D3),0)+IFERROR(SEARCH("mobility",D3),0)+IFERROR(SEARCH("automobile",D3),0)>0,"Logistics & Transport", IF(IFERROR(SEARCH("travel",D3),0)+IFERROR(SEARCH("hotel",D3),0)+IFERROR(SEARCH("booking",D3),0)+IFERROR(SEARCH("tourism",D3),0)>0,"Travel & Hospitality", IF(IFERROR(SEARCH("fashion",D3),0)+IFERROR(SEARCH("apparel",D3),0)+IFERROR(SEARCH("clothing",D3),0)+IFERROR(SEARCH("jewelry",D3),0)+IFERROR(SEARCH("beauty",D3),0)>0,"Fashion & Lifestyle", IF(IFERROR(SEARCH("media",D3),0)+IFERROR(SEARCH("entertainment",D3),0)+IFERROR(SEARCH("video",D3),0)+IFERROR(SEARCH("gaming",D3),0)+IFERROR(SEARCH("music",D3),0)+IFERROR(SEARCH("social",D3),0)>0,"Media & Entertainment", IF(IFERROR(SEARCH("agri",D3),0)+IFERROR(SEARCH("farm",D3),0)+IFERROR(SEARCH("agtech",D3),0)>0,"Agriculture", IF(IFERROR(SEARCH("real estate",D3),0)+IFERROR(SEARCH("property",D3),0)+IFERROR(SEARCH("housing",D3),0)>0,"Real Estate", IF(IFERROR(SEARCH("energy",D3),0)+IFERROR(SEARCH("solar",D3),0)+IFERROR(SEARCH("clean tech",D3),0)+IFERROR(SEARCH("waste",D3),0)>0,"Energy & Environment", IF(IFERROR(SEARCH("hr",D3),0)+IFERROR(SEARCH("recruit",D3),0)+IFERROR(SEARCH("hiring",D3),0)+IFERROR(SEARCH("job",D3),0)>0,"HR & Recruitment", "Others")))))))))))))) -> Logistics & Transport | R3: =IF(ISNUMBER(SEARCH("bang",F3)),"Bangalore",IF(ISNUMBER(SEARCH("beng",F3)),"Bangalore",IF(ISNUMBER(SEARCH("mumbai",F3)),"Mumbai",IF(ISNUMBER(SEARCH("delhi",F3)),"Delhi-NCR",IF(ISNUMBER(SEARCH("gurgaon",F3)),"Delhi-NCR",IF(ISNUMBER(SEARCH("gurugram",F3)),"Delhi-NCR",IF(ISNUMBER(SEARCH("noida",F3)),"Delhi-NCR",IF(ISNUMBER(SEARCH("faridabad",F3)),"Delhi-NCR",IF(ISNUMBER(SEARCH("chennai",F3)),"Chennai",IF(ISNUMBER(SEARCH("hyderabad",F3)),"Hyderabad",IF(ISNUMBER(SEARCH("pune",F3)),"Pune",IF(ISNUMBER(SEARCH("kolkata",F3)),"Kolkata",IF(ISNUMBER(SEARCH("ahmedabad",F3)),"Ahmedabad",IF(ISNUMBER(SEARCH("jaipur",F3)),"Jaipur",IF(ISNUMBER(SEARCH("coimbatore",F3)),"Coimbatore",IF(ISNUMBER(SEARCH("kochi",F3)),"Kerala Cities",IF(ISNUMBER(SEARCH("cochin",F3)),"Kerala Cities",IF(ISNUMBER(SEARCH("francisco",F3)),"USA",IF(ISNUMBER(SEARCH("new york",F3)),"USA",IF(ISNUMBER(SEARCH("california",F3)),"USA",IF(ISNUMBER(SEARCH("palo alto",F3)),"USA",IF(ISNUMBER(SEARCH("santa",F3)),"USA",IF(ISNUMBER(SEARCH("singapore",F3)),"Singapore",IF(ISNUMBER(SEARCH("london",F3)),"London/UK",IF(F3="","Unknown","Other Cities"))))))))))))))))))))))))) -> Delhi-NCR
A4: 3 | B4: 43839 | C4: Mamaearth | D4: Ecommerce | E4: Retailer of baby , toddler products | F4: Bengaluru | G4: Sequoia Capital India | H4: =IFERROR(TRIM(LEFT(G4,FIND(",",G4)-1)),TRIM(G4)) -> Sequoia Capital India | I4: =IF(TRIM(G4)="",0,LEN(G4)-LEN(SUBSTITUTE(G4,",",""))+1) -> 1 | J4: =IF(Table1[[#This Row],[Investor Count]]>1,"Yes","No") -> No | K4: Series B | L4: 18358860 | M4: =YEAR(B4) -> 2020 | N4: =TEXT(B4,"mmmm") -> January | O4: 176.1909 | P4: =IF(ISBLANK(K4),"Unknown",IF(OR(ISNUMBER(SEARCH("seed",K4)),ISNUMBER(SEARCH("Seed",K4))),"Seed",IF(ISNUMBER(SEARCH("Series A",K4)),"Series A",IF(ISNUMBER(SEARCH("Series B",K4)),"Series B",IF(ISNUMBER(SEARCH("Series C",K4)),"Series C",IF(ISNUMBER(SEARCH("Series D",K4)),"Series D",IF(ISNUMBER(SEARCH("Private Equity",K4)),"Private Equity","Other"))))))) -> Series B | Q4: =IF(IFERROR(SEARCH("ecom",D4),0)+IFERROR(SEARCH("commerce",D4),0)+IFERROR(SEARCH("retail",D4),0)>0,"E-Commerce", IF(IFERROR(SEARCH("fintech",D4),0)+IFERROR(SEARCH("finance",D4),0)+IFERROR(SEARCH("financial",D4),0)+IFERROR(SEARCH("lending",D4),0)+IFERROR(SEARCH("payment",D4),0)+IFERROR(SEARCH("banking",D4),0)+IFERROR(SEARCH("insurance",D4),0)>0,"FinTech", IF(IFERROR(SEARCH("tech",D4),0)+IFERROR(SEARCH("software",D4),0)+IFERROR(SEARCH("saas",D4),0)+IFERROR(SEARCH("ai",D4),0)+IFERROR(SEARCH("iot",D4),0)+IFERROR(SEARCH("cloud",D4),0)+IFERROR(SEARCH("data",D4),0)+IFERROR(SEARCH("analytics",D4),0)>0,"Technology", IF(IFERROR(SEARCH("food",D4),0)+IFERROR(SEARCH("restaurant",D4),0)+IFERROR(SEARCH("hospitality",D4),0)+IFERROR(SEARCH("beverage",D4),0)+IFERROR(SEARCH("delivery",D4),0)>0,"Food & Beverage", IF(IFERROR(SEARCH("health",D4),0)+IFERROR(SEARCH("medical",D4),0)+IFERROR(SEARCH("pharma",D4),0)+IFERROR(SEARCH("wellness",D4),0)+IFERROR(SEARCH("fitness",D4),0)>0,"Healthcare", IF(IFERROR(SEARCH("edu",D4),0)+IFERROR(SEARCH("learning",D4),0)+IFERROR(SEARCH("school",D4),0)+IFERROR(SEARCH("e-tech",D4),0)>0,"Education", IF(IFERROR(SEARCH("logistics",D4),0)+IFERROR(SEARCH("transport",D4),0)+IFERROR(SEARCH("delivery",D4),0)+IFERROR(SEARCH("mobility",D4),0)+IFERROR(SEARCH("automobile",D4),0)>0,"Logistics & Transport", IF(IFERROR(SEARCH("travel",D4),0)+IFERROR(SEARCH("hotel",D4),0)+IFERROR(SEARCH("booking",D4),0)+IFERROR(SEARCH("tourism",D4),0)>0,"Travel & Hospitality", IF(IFERROR(SEARCH("fashion",D4),0)+IFERROR(SEARCH("apparel",D4),0)+IFERROR(SEARCH("clothing",D4),0)+IFERROR(SEARCH("jewelry",D4),0)+IFERROR(SEARCH("beauty",D4),0)>0,"Fashion & Lifestyle", IF(IFERROR(SEARCH("media",D4),0)+IFERROR(SEARCH("entertainment",D4),0)+IFERROR(SEARCH("video",D4),0)+IFERROR(SEARCH("gaming",D4),0)+IFERROR(SEARCH("music",D4),0)+IFERROR(SEARCH("social",D4),0)>0,"Media & Entertainment", IF(IFERROR(SEARCH("agri",D4),0)+IFERROR(SEARCH("farm",D4),0)+IFERROR(SEARCH("agtech",D4),0)>0,"Agriculture", IF(IFERROR(SEARCH("real estate",D4),0)+IFERROR(SEARCH("property",D4),0)+IFERROR(SEARCH("housing",D4),0)>0,"Real Estate", IF(IFERROR(SEARCH("energy",D4),0)+IFERROR(SEARCH("solar",D4),0)+IFERROR(SEARCH("clean tech",D4),0)+IFERROR(SEARCH("waste",D4),0)>0,"Energy & Environment", IF(IFERROR(SEARCH("hr",D4),0)+IFERROR(SEARCH("recruit",D4),0)+IFERROR(SEARCH("hiring",D4),0)+IFERROR(SEARCH("job",D4),0)>0,"HR & Recruitment", "Others")))))))))))))) -> E-Commerce | R4: =IF(ISNUMBER(SEARCH("bang",F4)),"Bangalore",IF(ISNUMBER(SEARCH("beng",F4)),"Bangalore",IF(ISNUMBER(SEARCH("mumbai",F4)),"Mumbai",IF(ISNUMBER(SEARCH("delhi",F4)),"Delhi-NCR",IF(ISNUMBER(SEARCH("gurgaon",F4)),"Delhi-NCR",IF(ISNUMBER(SEARCH("gurugram",F4)),"Delhi-NCR",IF(ISNUMBER(SEARCH("noida",F4)),"Delhi-NCR",IF(ISNUMBER(SEARCH("faridabad",F4)),"Delhi-NCR",IF(ISNUMBER(SEARCH("chennai",F4)),"Chennai",IF(ISNUMBER(SEARCH("hyderabad",F4)),"Hyderabad",IF(ISNUMBER(SEARCH("pune",F4)),"Pune",IF(ISNUMBER(SEARCH("kolkata",F4)),"Kolkata",IF(ISNUMBER(SEARCH("ahmedabad",F4)),"Ahmedabad",IF(ISNUMBER(SEARCH("jaipur",F4)),"Jaipur",IF(ISNUMBER(SEARCH("coimbatore",F4)),"Coimbatore",IF(ISNUMBER(SEARCH("kochi",F4)),"Kerala Cities",IF(ISNUMBER(SEARCH("cochin",F4)),"Kerala Cities",IF(ISNUMBER(SEARCH("francisco",F4)),"USA",IF(ISNUMBER(SEARCH("new york",F4)),"USA",IF(ISNUMBER(SEARCH("california",F4)),"USA",IF(ISNUMBER(SEARCH("palo alto",F4)),"USA",IF(ISNUMBER(SEARCH("santa",F4)),"USA",IF(ISNUMBER(SEARCH("singapore",F4)),"Singapore",IF(ISNUMBER(SEARCH("london",F4)),"London/UK",IF(F4="","Unknown","Other Cities"))))))))))))))))))))))))) -> Bangalore
A5: 4 | B5: 43832 | C5: Wealthbucket | D5: FinTech | E5: Online Investment | F5: New Delhi | G5: Vinod Khatumal | H5: =IFERROR(TRIM(LEFT(G5,FIND(",",G5)-1)),TRIM(G5)) -> Vinod Khatumal | I5: =IF(TRIM(G5)="",0,LEN(G5)-LEN(SUBSTITUTE(G5,",",""))+1) -> 1 | J5: =IF(Table1[[#This Row],[Investor Count]]>1,"Yes","No") -> No | K5: Pre-series A | L5: 3000000 | M5: =YEAR(B5) -> 2020 | N5: =TEXT(B5,"mmmm") -> January | O5: 28.79115 | P5: =IF(ISBLANK(K5),"Unknown",IF(OR(ISNUMBER(SEARCH("seed",K5)),ISNUMBER(SEARCH("Seed",K5))),"Seed",IF(ISNUMBER(SEARCH("Series A",K5)),"Series A",IF(ISNUMBER(SEARCH("Series B",K5)),"Series B",IF(ISNUMBER(SEARCH("Series C",K5)),"Series C",IF(ISNUMBER(SEARCH("Series D",K5)),"Series D",IF(ISNUMBER(SEARCH("Private Equity",K5)),"Private Equity","Other"))))))) -> Series A | Q5: =IF(IFERROR(SEARCH("ecom",D5),0)+IFERROR(SEARCH("commerce",D5),0)+IFERROR(SEARCH("retail",D5),0)>0,"E-Commerce", IF(IFERROR(SEARCH("fintech",D5),0)+IFERROR(SEARCH("finance",D5),0)+IFERROR(SEARCH("financial",D5),0)+IFERROR(SEARCH("lending",D5),0)+IFERROR(SEARCH("payment",D5),0)+IFERROR(SEARCH("banking",D5),0)+IFERROR(SEARCH("insurance",D5),0)>0,"FinTech", IF(IFERROR(SEARCH("tech",D5),0)+IFERROR(SEARCH("software",D5),0)+IFERROR(SEARCH("saas",D5),0)+IFERROR(SEARCH("ai",D5),0)+IFERROR(SEARCH("iot",D5),0)+IFERROR(SEARCH("cloud",D5),0)+IFERROR(SEARCH("data",D5),0)+IFERROR(SEARCH("analytics",D5),0)>0,"Technology", IF(IFERROR(SEARCH("food",D5),0)+IFERROR(SEARCH("restaurant",D5),0)+IFERROR(SEARCH("hospitality",D5),0)+IFERROR(SEARCH("beverage",D5),0)+IFERROR(SEARCH("delivery",D5),0)>0,"Food & Beverage", IF(IFERROR(SEARCH("health",D5),0)+IFERROR(SEARCH("medical",D5),0)+IFERROR(SEARCH("pharma",D5),0)+IFERROR(SEARCH("wellness",D5),0)+IFERROR(SEARCH("fitness",D5),0)>0,"Healthcare", IF(IFERROR(SEARCH("edu",D5),0)+IFERROR(SEARCH("learning",D5),0)+IFERROR(SEARCH("school",D5),0)+IFERROR(SEARCH("e-tech",D5),0)>0,"Education", IF(IFERROR(SEARCH("logistics",D5),0)+IFERROR(SEARCH("transport",D5),0)+IFERROR(SEARCH("delivery",D5),0)+IFERROR(SEARCH("mobility",D5),0)+IFERROR(SEARCH("automobile",D5),0)>0,"Logistics & Transport", IF(IFERROR(SEARCH("travel",D5),0)+IFERROR(SEARCH("hotel",D5),0)+IFERROR(SEARCH("booking",D5),0)+IFERROR(SEARCH("tourism",D5),0)>0,"Travel & Hospitality", IF(IFERROR(SEARCH("fashion",D5),0)+IFERROR(SEARCH("apparel",D5),0)+IFERROR(SEARCH("clothing",D5),0)+IFERROR(SEARCH("jewelry",D5),0)+IFERROR(SEARCH("beauty",D5),0)>0,"Fashion & Lifestyle", IF(IFERROR(SEARCH("media",D5),0)+IFERROR(SEARCH("entertainment",D5),0)+IFERROR(SEARCH("video",D5),0)+IFERROR(SEARCH("gaming",D5),0)+IFERROR(SEARCH("music",D5),0)+IFERROR(SEARCH("social",D5),0)>0,"Media & Entertainment", IF(IFERROR(SEARCH("agri",D5),0)+IFERROR(SEARCH("farm",D5),0)+IFERROR(SEARCH("agtech",D5),0)>0,"Agriculture", IF(IFERROR(SEARCH("real estate",D5),0)+IFERROR(SEARCH("property",D5),0)+IFERROR(SEARCH("housing",D5),0)>0,"Real Estate", IF(IFERROR(SEARCH("energy",D5),0)+IFERROR(SEARCH("solar",D5),0)+IFERROR(SEARCH("clean tech",D5),0)+IFERROR(SEARCH("waste",D5),0)>0,"Energy & Environment", IF(IFERROR(SEARCH("hr",D5),0)+IFERROR(SEARCH("recruit",D5),0)+IFERROR(SEARCH("hiring",D5),0)+IFERROR(SEARCH("job",D5),0)>0,"HR & Recruitment", "Others")))))))))))))) -> FinTech | R5: =IF(ISNUMBER(SEARCH("bang",F5)),"Bangalore",IF(ISNUMBER(SEARCH("beng",F5)),"Bangalore",IF(ISNUMBER(SEARCH("mumbai",F5)),"Mumbai",IF(ISNUMBER(SEARCH("delhi",F5)),"Delhi-NCR",IF(ISNUMBER(SEARCH("gurgaon",F5)),"Delhi-NCR",IF(ISNUMBER(SEARCH("gurugram",F5)),"Delhi-NCR",IF(ISNUMBER(SEARCH("noida",F5)),"Delhi-NCR",IF(ISNUMBER(SEARCH("faridabad",F5)),"Delhi-NCR",IF(ISNUMBER(SEARCH("chennai",F5)),"Chennai",IF(ISNUMBER(SEARCH("hyderabad",F5)),"Hyderabad",IF(ISNUMBER(SEARCH("pune",F5)),"Pune",IF(ISNUMBER(SEARCH("kolkata",F5)),"Kolkata",IF(ISNUMBER(SEARCH("ahmedabad",F5)),"Ahmedabad",IF(ISNUMBER(SEARCH("jaipur",F5)),"Jaipur",IF(ISNUMBER(SEARCH("coimbatore",F5)),"Coimbatore",IF(ISNUMBER(SEARCH("kochi",F5)),"Kerala Cities",IF(ISNUMBER(SEARCH("cochin",F5)),"Kerala Cities",IF(ISNUMBER(SEARCH("francisco",F5)),"USA",IF(ISNUMBER(SEARCH("new york",F5)),"USA",IF(ISNUMBER(SEARCH("california",F5)),"USA",IF(ISNUMBER(SEARCH("palo alto",F5)),"USA",IF(ISNUMBER(SEARCH("santa",F5)),"USA",IF(ISNUMBER(SEARCH("singapore",F5)),"Singapore",IF(ISNUMBER(SEARCH("london",F5)),"London/UK",IF(F5="","Unknown","Other Cities"))))))))))))))))))))))))) -> Delhi-NCR
A6: 5 | B6: 43832 | C6: Fashor | D6: Fashion & Apparel | E6: Embroiled Clothes For Women | F6: Mumbai | G6: Sprout Venture Partners | H6: =IFERROR(TRIM(LEFT(G6,FIND(",",G6)-1)),TRIM(G6)) -> Sprout Venture Partners | I6: =IF(TRIM(G6)="",0,LEN(G6)-LEN(SUBSTITUTE(G6,",",""))+1) -> 1 | J6: =IF(Table1[[#This Row],[Investor Count]]>1,"Yes","No") -> No | K6: Seed Round | L6: 1800000 | M6: =YEAR(B6) -> 2020 | N6: =TEXT(B6,"mmmm") -> January | O6: 17.27469 | P6: =IF(ISBLANK(K6),"Unknown",IF(OR(ISNUMBER(SEARCH("seed",K6)),ISNUMBER(SEARCH("Seed",K6))),"Seed",IF(ISNUMBER(SEARCH("Series A",K6)),"Series A",IF(ISNUMBER(SEARCH("Series B",K6)),"Series B",IF(ISNUMBER(SEARCH("Series C",K6)),"Series C",IF(ISNUMBER(SEARCH("Series D",K6)),"Series D",IF(ISNUMBER(SEARCH("Private Equity",K6)),"Private Equity","Other"))))))) -> Seed | Q6: =IF(IFERROR(SEARCH("ecom",D6),0)+IFERROR(SEARCH("commerce",D6),0)+IFERROR(SEARCH("retail",D6),0)>0,"E-Commerce", IF(IFERROR(SEARCH("fintech",D6),0)+IFERROR(SEARCH("finance",D6),0)+IFERROR(SEARCH("financial",D6),0)+IFERROR(SEARCH("lending",D6),0)+IFERROR(SEARCH("payment",D6),0)+IFERROR(SEARCH("banking",D6),0)+IFERROR(SEARCH("insurance",D6),0)>0,"FinTech", IF(IFERROR(SEARCH("tech",D6),0)+IFERROR(SEARCH("software",D6),0)+IFERROR(SEARCH("saas",D6),0)+IFERROR(SEARCH("ai",D6),0)+IFERROR(SEARCH("iot",D6),0)+IFERROR(SEARCH("cloud",D6),0)+IFERROR(SEARCH("data",D6),0)+IFERROR(SEARCH("analytics",D6),0)>0,"Technology", IF(IFERROR(SEARCH("food",D6),0)+IFERROR(SEARCH("restaurant",D6),0)+IFERROR(SEARCH("hospitality",D6),0)+IFERROR(SEARCH("beverage",D6),0)+IFERROR(SEARCH("delivery",D6),0)>0,"Food & Beverage", IF(IFERROR(SEARCH("health",D6),0)+IFERROR(SEARCH("medical",D6),0)+IFERROR(SEARCH("pharma",D6),0)+IFERROR(SEARCH("wellness",D6),0)+IFERROR(SEARCH("fitness",D6),0)>0,"Healthcare", IF(IFERROR(SEARCH("edu",D6),0)+IFERROR(SEARCH("learning",D6),0)+IFERROR(SEARCH("school",D6),0)+IFERROR(SEARCH("e-tech",D6),0)>0,"Education", IF(IFERROR(SEARCH("logistics",D6),0)+IFERROR(SEARCH("transport",D6),0)+IFERROR(SEARCH("delivery",D6),0)+IFERROR(SEARCH("mobility",D6),0)+IFERROR(SEARCH("automobile",D6),0)>0,"Logistics & Transport", IF(IFERROR(SEARCH("travel",D6),0)+IFERROR(SEARCH("hotel",D6),0)+IFERROR(SEARCH("booking",D6),0)+IFERROR(SEARCH("tourism",D6),0)>0,"Travel & Hospitality", IF(IFERROR(SEARCH("fashion",D6),0)+IFERROR(SEARCH("apparel",D6),0)+IFERROR(SEARCH("clothing",D6),0)+IFERROR(SEARCH("jewelry",D6),0)+IFERROR(SEARCH("beauty",D6),0)>0,"Fashion & Lifestyle", IF(IFERROR(SEARCH("media",D6),0)+IFERROR(SEARCH("entertainment",D6),0)+IFERROR(SEARCH("video",D6),0)+IFERROR(SEARCH("gaming",D6),0)+IFERROR(SEARCH("music",D6),0)+IFERROR(SEARCH("social",D6),0)>0,"Media & Entertainment", IF(IFERROR(SEARCH("agri",D6),0)+IFERROR(SEARCH("farm",D6),0)+IFERROR(SEARCH("agtech",D6),0)>0,"Agriculture", IF(IFERROR(SEARCH("real estate",D6),0)+IFERROR(SEARCH("property",D6),0)+IFERROR(SEARCH("housing",D6),0)>0,"Real Estate", IF(IFERROR(SEARCH("energy",D6),0)+IFERROR(SEARCH("solar",D6),0)+IFERROR(SEARCH("clean tech",D6),0)+IFERROR(SEARCH("waste",D6),0)>0,"Energy & Environment", IF(IFERROR(SEARCH("hr",D6),0)+IFERROR(SEARCH("recruit",D6),0)+IFERROR(SEARCH("hiring",D6),0)+IFERROR(SEARCH("job",D6),0)>0,"HR & Recruitment", "Others")))))))))))))) -> Fashion & Lifestyle | R6: =IF(ISNUMBER(SEARCH("bang",F6)),"Bangalore",IF(ISNUMBER(SEARCH("beng",F6)),"Bangalore",IF(ISNUMBER(SEARCH("mumbai",F6)),"Mumbai",IF(ISNUMBER(SEARCH("delhi",F6)),"Delhi-NCR",IF(ISNUMBER(SEARCH("gurgaon",F6)),"Delhi-NCR",IF(ISNUMBER(SEARCH("gurugram",F6)),"Delhi-NCR",IF(ISNUMBER(SEARCH("noida",F6)),"Delhi-NCR",IF(ISNUMBER(SEARCH("faridabad",F6)),"Delhi-NCR",IF(ISNUMBER(SEARCH("chennai",F6)),"Chennai",IF(ISNUMBER(SEARCH("hyderabad",F6)),"Hyderabad",IF(ISNUMBER(SEARCH("pune",F6)),"Pune",IF(ISNUMBER(SEARCH("kolkata",F6)),"Kolkata",IF(ISNUMBER(SEARCH("ahmedabad",F6)),"Ahmedabad",IF(ISNUMBER(SEARCH("jaipur",F6)),"Jaipur",IF(ISNUMBER(SEARCH("coimbatore",F6)),"Coimbatore",IF(ISNUMBER(SEARCH("kochi",F6)),"Kerala Cities",IF(ISNUMBER(SEARCH("cochin",F6)),"Kerala Cities",IF(ISNUMBER(SEARCH("francisco",F6)),"USA",IF(ISNUMBER(SEARCH("new york",F6)),"USA",IF(ISNUMBER(SEARCH("california",F6)),"USA",IF(ISNUMBER(SEARCH("palo alto",F6)),"USA",IF(ISNUMBER(SEARCH("santa",F6)),"USA",IF(ISNUMBER(SEARCH("singapore",F6)),"Singapore",IF(ISNUMBER(SEARCH("london",F6)),"London/UK",IF(F6="","Unknown","Other Cities"))))))))))))))))))))))))) -> Mumbai
A7: 6 | B7: 43843 | C7: Po | D7: Logistics | E7: Open-market, freight management platform | F7: Chennai | G7: Chiratae Ventures | H7: =IFERROR(TRIM(LEFT(G7,FIND(",",G7)-1)),TRIM(G7)) -> Chiratae Ventures | I7: =IF(TRIM(G7)="",0,LEN(G7)-LEN(SUBSTITUTE(G7,",",""))+1) -> 1 | J7: =IF(Table1[[#This Row],[Investor Count]]>1,"Yes","No") -> No | K7: Series A | L7: 9000000 | M7: =YEAR(B7) -> 2020 | N7: =TEXT(B7,"mmmm") -> January | O7: 86.37345 | P7: =IF(ISBLANK(K7),"Unknown",IF(OR(ISNUMBER(SEARCH("seed",K7)),ISNUMBER(SEARCH("Seed",K7))),"Seed",IF(ISNUMBER(SEARCH("Series A",K7)),"Series A",IF(ISNUMBER(SEARCH("Series B",K7)),"Series B",IF(ISNUMBER(SEARCH("Series C",K7)),"Series C",IF(ISNUMBER(SEARCH("Series D",K7)),"Series D",IF(ISNUMBER(SEARCH("Private Equity",K7)),"Private Equity","Other"))))))) -> Series A | Q7: =IF(IFERROR(SEARCH("ecom",D7),0)+IFERROR(SEARCH("commerce",D7),0)+IFERROR(SEARCH("retail",D7),0)>0,"E-Commerce", IF(IFERROR(SEARCH("fintech",D7),0)+IFERROR(SEARCH("finance",D7),0)+IFERROR(SEARCH("financial",D7),0)+IFERROR(SEARCH("lending",D7),0)+IFERROR(SEARCH("payment",D7),0)+IFERROR(SEARCH("banking",D7),0)+IFERROR(SEARCH("insurance",D7),0)>0,"FinTech", IF(IFERROR(SEARCH("tech",D7),0)+IFERROR(SEARCH("software",D7),0)+IFERROR(SEARCH("saas",D7),0)+IFERROR(SEARCH("ai",D7),0)+IFERROR(SEARCH("iot",D7),0)+IFERROR(SEARCH("cloud",D7),0)+IFERROR(SEARCH("data",D7),0)+IFERROR(SEARCH("analytics",D7),0)>0,"Technology", IF(IFERROR(SEARCH("food",D7),0)+IFERROR(SEARCH("restaurant",D7),0)+IFERROR(SEARCH("hospitality",D7),0)+IFERROR(SEARCH("beverage",D7),0)+IFERROR(SEARCH("delivery",D7),0)>0,"Food & Beverage", IF(IFERROR(SEARCH("health",D7),0)+IFERROR(SEARCH("medical",D7),0)+IFERROR(SEARCH("pharma",D7),0)+IFERROR(SEARCH("wellness",D7),0)+IFERROR(SEARCH("fitness",D7),0)>0,"Healthcare", IF(IFERROR(SEARCH("edu",D7),0)+IFERROR(SEARCH("learning",D7),0)+IFERROR(SEARCH("school",D7),0)+IFERROR(SEARCH("e-tech",D7),0)>0,"Education", IF(IFERROR(SEARCH("logistics",D7),0)+IFERROR(SEARCH("transport",D7),0)+IFERROR(SEARCH("delivery",D7),0)+IFERROR(SEARCH("mobility",D7),0)+IFERROR(SEARCH("automobile",D7),0)>0,"Logistics & Transport", IF(IFERROR(SEARCH("travel",D7),0)+IFERROR(SEARCH("hotel",D7),0)+IFERROR(SEARCH("booking",D7),0)+IFERROR(SEARCH("tourism",D7),0)>0,"Travel & Hospitality", IF(IFERROR(SEARCH("fashion",D7),0)+IFERROR(SEARCH("apparel",D7),0)+IFERROR(SEARCH("clothing",D7),0)+IFERROR(SEARCH("jewelry",D7),0)+IFERROR(SEARCH("beauty",D7),0)>0,"Fashion & Lifestyle", IF(IFERROR(SEARCH("media",D7),0)+IFERROR(SEARCH("entertainment",D7),0)+IFERROR(SEARCH("video",D7),0)+IFERROR(SEARCH("gaming",D7),0)+IFERROR(SEARCH("music",D7),0)+IFERROR(SEARCH("social",D7),0)>0,"Media & Entertainment", IF(IFERROR(SEARCH("agri",D7),0)+IFERROR(SEARCH("farm",D7),0)+IFERROR(SEARCH("agtech",D7),0)>0,"Agriculture", IF(IFERROR(SEARCH("real estate",D7),0)+IFERROR(SEARCH("property",D7),0)+IFERROR(SEARCH("housing",D7),0)>0,"Real Estate", IF(IFERROR(SEARCH("energy",D7),0)+IFERROR(SEARCH("solar",D7),0)+IFERROR(SEARCH("clean tech",D7),0)+IFERROR(SEARCH("waste",D7),0)>0,"Energy & Environment", IF(IFERROR(SEARCH("hr",D7),0)+IFERROR(SEARCH("recruit",D7),0)+IFERROR(SEARCH("hiring",D7),0)+IFERROR(SEARCH("job",D7),0)>0,"HR & Recruitment", "Others")))))))))))))) -> Logistics & Transport | R7: =IF(ISNUMBER(SEARCH("bang",F7)),"Bangalore",IF(ISNUMBER(SEARCH("beng",F7)),"Bangalore",IF(ISNUMBER(SEARCH("mumbai",F7)),"Mumbai",IF(ISNUMBER(SEARCH("delhi",F7)),"Delhi-NCR",IF(ISNUMBER(SEARCH("gurgaon",F7)),"Delhi-NCR",IF(ISNUMBER(SEARCH("gurugram",F7)),"Delhi-NCR",IF(ISNUMBER(SEARCH("noida",F7)),"Delhi-NCR",IF(ISNUMBER(SEARCH("faridabad",F7)),"Delhi-NCR",IF(ISNUMBER(SEARCH("chennai",F7)),"Chennai",IF(ISNUMBER(SEARCH("hyderabad",F7)),"Hyderabad",IF(ISNUMBER(SEARCH("pune",F7)),"Pune",IF(ISNUMBER(SEARCH("kolkata",F7)),"Kolkata",IF(ISNUMBER(SEARCH("ahmedabad",F7)),"Ahmedabad",IF(ISNUMBER(SEARCH("jaipur",F7)),"Jaipur",IF(ISNUMBER(SEARCH("coimbatore",F7)),"Coimbatore",IF(ISNUMBER(SEARCH("kochi",F7)),"Kerala Cities",IF(ISNUMBER(SEARCH("cochin",F7)),"Kerala Cities",IF(ISNUMBER(SEARCH("francisco",F7)),"USA",IF(ISNUMBER(SEARCH("new york",F7)),"USA",IF(ISNUMBER(SEARCH("california",F7)),"USA",IF(ISNUMBER(SEARCH("palo alto",F7)),"USA",IF(ISNUMBER(SEARCH("santa",F7)),"USA",IF(ISNUMBER(SEARCH("singapore",F7)),"Singapore",IF(ISNUMBER(SEARCH("london",F7)),"London/UK",IF(F7="","Unknown","Other Cities"))))))))))))))))))))))))) -> Chennai
A8: 7 | B8: 43840 | C8: Zomato | D8: Hospitality | E8: Online Food Delivery Platform | F8: Gurgaon | G8: Ant Financial | H8: =IFERROR(TRIM(LEFT(G8,FIND(",",G8)-1)),TRIM(G8)) -> Ant Financial | I8: =IF(TRIM(G8)="",0,LEN(G8)-LEN(SUBSTITUTE(G8,",",""))+1) -> 1 | J8: =IF(Table1[[#This Row],[Investor Count]]>1,"Yes","No") -> No | K8: Private Equity Round | L8: 150000000 | M8: =YEAR(B8) -> 2020 | N8: =TEXT(B8,"mmmm") -> January | O8: 1439.5575 | P8: =IF(ISBLANK(K8),"Unknown",IF(OR(ISNUMBER(SEARCH("seed",K8)),ISNUMBER(SEARCH("Seed",K8))),"Seed",IF(ISNUMBER(SEARCH("Series A",K8)),"Series A",IF(ISNUMBER(SEARCH("Series B",K8)),"Series B",IF(ISNUMBER(SEARCH("Series C",K8)),"Series C",IF(ISNUMBER(SEARCH("Series D",K8)),"Series D",IF(ISNUMBER(SEARCH("Private Equity",K8)),"Private Equity","Other"))))))) -> Private Equity | Q8: =IF(IFERROR(SEARCH("ecom",D8),0)+IFERROR(SEARCH("commerce",D8),0)+IFERROR(SEARCH("retail",D8),0)>0,"E-Commerce", IF(IFERROR(SEARCH("fintech",D8),0)+IFERROR(SEARCH("finance",D8),0)+IFERROR(SEARCH("financial",D8),0)+IFERROR(SEARCH("lending",D8),0)+IFERROR(SEARCH("payment",D8),0)+IFERROR(SEARCH("banking",D8),0)+IFERROR(SEARCH("insurance",D8),0)>0,"FinTech", IF(IFERROR(SEARCH("tech",D8),0)+IFERROR(SEARCH("software",D8),0)+IFERROR(SEARCH("saas",D8),0)+IFERROR(SEARCH("ai",D8),0)+IFERROR(SEARCH("iot",D8),0)+IFERROR(SEARCH("cloud",D8),0)+IFERROR(SEARCH("data",D8),0)+IFERROR(SEARCH("analytics",D8),0)>0,"Technology", IF(IFERROR(SEARCH("food",D8),0)+IFERROR(SEARCH("restaurant",D8),0)+IFERROR(SEARCH("hospitality",D8),0)+IFERROR(SEARCH("beverage",D8),0)+IFERROR(SEARCH("delivery",D8),0)>0,"Food & Beverage", IF(IFERROR(SEARCH("health",D8),0)+IFERROR(SEARCH("medical",D8),0)+IFERROR(SEARCH("pharma",D8),0)+IFERROR(SEARCH("wellness",D8),0)+IFERROR(SEARCH("fitness",D8),0)>0,"Healthcare", IF(IFERROR(SEARCH("edu",D8),0)+IFERROR(SEARCH("learning",D8),0)+IFERROR(SEARCH("school",D8),0)+IFERROR(SEARCH("e-tech",D8),0)>0,"Education", IF(IFERROR(SEARCH("logistics",D8),0)+IFERROR(SEARCH("transport",D8),0)+IFERROR(SEARCH("delivery",D8),0)+IFERROR(SEARCH("mobility",D8),0)+IFERROR(SEARCH("automobile",D8),0)>0,"Logistics & Transport", IF(IFERROR(SEARCH("travel",D8),0)+IFERROR(SEARCH("hotel",D8),0)+IFERROR(SEARCH("booking",D8),0)+IFERROR(SEARCH("tourism",D8),0)>0,"Travel & Hospitality", IF(IFERROR(SEARCH("fashion",D8),0)+IFERROR(SEARCH("apparel",D8),0)+IFERROR(SEARCH("clothing",D8),0)+IFERROR(SEARCH("jewelry",D8),0)+IFERROR(SEARCH("beauty",D8),0)>0,"Fashion & Lifestyle", IF(IFERROR(SEARCH("media",D8),0)+IFERROR(SEARCH("entertainment",D8),0)+IFERROR(SEARCH("video",D8),0)+IFERROR(SEARCH("gaming",D8),0)+IFERROR(SEARCH("music",D8),0)+IFERROR(SEARCH("social",D8),0)>0,"Media & Entertainment", IF(IFERROR(SEARCH("agri",D8),0)+IFERROR(SEARCH("farm",D8),0)+IFERROR(SEARCH("agtech",D8),0)>0,"Agriculture", IF(IFERROR(SEARCH("real estate",D8),0)+IFERROR(SEARCH("property",D8),0)+IFERROR(SEARCH("housing",D8),0)>0,"Real Estate", IF(IFERROR(SEARCH("energy",D8),0)+IFERROR(SEARCH("solar",D8),0)+IFERROR(SEARCH("clean tech",D8),0)+IFERROR(SEARCH("waste",D8),0)>0,"Energy & Environment", IF(IFERROR(SEARCH("hr",D8),0)+IFERROR(SEARCH("recruit",D8),0)+IFERROR(SEARCH("hiring",D8),0)+IFERROR(SEARCH("job",D8),0)>0,"HR & Recruitment", "Others")))))))))))))) -> Food & Beverage | R8: =IF(ISNUMBER(SEARCH("bang",F8)),"Bangalore",IF(ISNUMBER(SEARCH("beng",F8)),"Bangalore",IF(ISNUMBER(SEARCH("mumbai",F8)),"Mumbai",IF(ISNUMBER(SEARCH("delhi",F8)),"Delhi-NCR",IF(ISNUMBER(SEARCH("gurgaon",F8)),"Delhi-NCR",IF(ISNUMBER(SEARCH("gurugram",F8)),"Delhi-NCR",IF(ISNUMBER(SEARCH("noida",F8)),"Delhi-NCR",IF(ISNUMBER(SEARCH("faridabad",F8)),"Delhi-NCR",IF(ISNUMBER(SEARCH("chennai",F8)),"Chennai",IF(ISNUMBER(SEARCH("hyderabad",F8)),"Hyderabad",IF(ISNUMBER(SEARCH("pune",F8)),"Pune",IF(ISNUMBER(SEARCH("kolkata",F8)),"Kolkata",IF(ISNUMBER(SEARCH("ahmedabad",F8)),"Ahmedabad",IF(ISNUMBER(SEARCH("jaipur",F8)),"Jaipur",IF(ISNUMBER(SEARCH("coimbatore",F8)),"Coimbatore",IF(ISNUMBER(SEARCH("kochi",F8)),"Kerala Cities",IF(ISNUMBER(SEARCH("cochin",F8)),"Kerala Cities",IF(ISNUMBER(SEARCH("francisco",F8)),"USA",IF(ISNUMBER(SEARCH("new york",F8)),"USA",IF(ISNUMBER(SEARCH("california",F8)),"USA",IF(ISNUMBER(SEARCH("palo alto",F8)),"USA",IF(ISNUMBER(SEARCH("santa",F8)),"USA",IF(ISNUMBER(SEARCH("singapore",F8)),"Singapore",IF(ISNUMBER(SEARCH("london",F8)),"London/UK",IF(F8="","Unknown","Other Cities"))))))))))))))))))))))))) -> Delhi-NCR
A9: 8 | B9: 43811 | C9: Ecozen | D9: Technology | E9: Agritech | F9: Pune | G9: Sathguru Catalyzer Advisors | H9: =IFERROR(TRIM(LEFT(G9,FIND(",",G9)-1)),TRIM(G9)) -> Sathguru Catalyzer Advisors | I9: =IF(TRIM(G9)="",0,LEN(G9)-LEN(SUBSTITUTE(G9,",",""))+1) -> 1 | J9: =IF(Table1[[#This Row],[Investor Count]]>1,"Yes","No") -> No | K9: Series A | L9: 6000000 | M9: =YEAR(B9) -> 2019 | N9: =TEXT(B9,"mmmm") -> December | O9: 57.5823 | P9: =IF(ISBLANK(K9),"Unknown",IF(OR(ISNUMBER(SEARCH("seed",K9)),ISNUMBER(SEARCH("Seed",K9))),"Seed",IF(ISNUMBER(SEARCH("Series A",K9)),"Series A",IF(ISNUMBER(SEARCH("Series B",K9)),"Series B",IF(ISNUMBER(SEARCH("Series C",K9)),"Series C",IF(ISNUMBER(SEARCH("Series D",K9)),"Series D",IF(ISNUMBER(SEARCH("Private Equity",K9)),"Private Equity","Other"))))))) -> Series A | Q9: =IF(IFERROR(SEARCH("ecom",D9),0)+IFERROR(SEARCH("commerce",D9),0)+IFERROR(SEARCH("retail",D9),0)>0,"E-Commerce", IF(IFERROR(SEARCH("fintech",D9),0)+IFERROR(SEARCH("finance",D9),0)+IFERROR(SEARCH("financial",D9),0)+IFERROR(SEARCH("lending",D9),0)+IFERROR(SEARCH("payment",D9),0)+IFERROR(SEARCH("banking",D9),0)+IFERROR(SEARCH("insurance",D9),0)>0,"FinTech", IF(IFERROR(SEARCH("tech",D9),0)+IFERROR(SEARCH("software",D9),0)+IFERROR(SEARCH("saas",D9),0)+IFERROR(SEARCH("ai",D9),0)+IFERROR(SEARCH("iot",D9),0)+IFERROR(SEARCH("cloud",D9),0)+IFERROR(SEARCH("data",D9),0)+IFERROR(SEARCH("analytics",D9),0)>0,"Technology", IF(IFERROR(SEARCH("food",D9),0)+IFERROR(SEARCH("restaurant",D9),0)+IFERROR(SEARCH("hospitality",D9),0)+IFERROR(SEARCH("beverage",D9),0)+IFERROR(SEARCH("delivery",D9),0)>0,"Food & Beverage", IF(IFERROR(SEARCH("health",D9),0)+IFERROR(SEARCH("medical",D9),0)+IFERROR(SEARCH("pharma",D9),0)+IFERROR(SEARCH("wellness",D9),0)+IFERROR(SEARCH("fitness",D9),0)>0,"Healthcare", IF(IFERROR(SEARCH("edu",D9),0)+IFERROR(SEARCH("learning",D9),0)+IFERROR(SEARCH("school",D9),0)+IFERROR(SEARCH("e-tech",D9),0)>0,"Education", IF(IFERROR(SEARCH("logistics",D9),0)+IFERROR(SEARCH("transport",D9),0)+IFERROR(SEARCH("delivery",D9),0)+IFERROR(SEARCH("mobility",D9),0)+IFERROR(SEARCH("automobile",D9),0)>0,"Logistics & Transport", IF(IFERROR(SEARCH("travel",D9),0)+IFERROR(SEARCH("hotel",D9),0)+IFERROR(SEARCH("booking",D9),0)+IFERROR(SEARCH("tourism",D9),0)>0,"Travel & Hospitality", IF(IFERROR(SEARCH("fashion",D9),0)+IFERROR(SEARCH("apparel",D9),0)+IFERROR(SEARCH("clothing",D9),0)+IFERROR(SEARCH("jewelry",D9),0)+IFERROR(SEARCH("beauty",D9),0)>0,"Fashion & Lifestyle", IF(IFERROR(SEARCH("media",D9),0)+IFERROR(SEARCH("entertainment",D9),0)+IFERROR(SEARCH("video",D9),0)+IFERROR(SEARCH("gaming",D9),0)+IFERROR(SEARCH("music",D9),0)+IFERROR(SEARCH("social",D9),0)>0,"Media & Entertainment", IF(IFERROR(SEARCH("agri",D9),0)+IFERROR(SEARCH("farm",D9),0)+IFERROR(SEARCH("agtech",D9),0)>0,"Agriculture", IF(IFERROR(SEARCH("real estate",D9),0)+IFERROR(SEARCH("property",D9),0)+IFERROR(SEARCH("housing",D9),0)>0,"Real Estate", IF(IFERROR(SEARCH("energy",D9),0)+IFERROR(SEARCH("solar",D9),0)+IFERROR(SEARCH("clean tech",D9),0)+IFERROR(SEARCH("waste",D9),0)>0,"Energy & Environment", IF(IFERROR(SEARCH("hr",D9),0)+IFERROR(SEARCH("recruit",D9),0)+IFERROR(SEARCH("hiring",D9),0)+IFERROR(SEARCH("job",D9),0)>0,"HR & Recruitment", "Others")))))))))))))) -> Technology | R9: =IF(ISNUMBER(SEARCH("bang",F9)),"Bangalore",IF(ISNUMBER(SEARCH("beng",F9)),"Bangalore",IF(ISNUMBER(SEARCH("mumbai",F9)),"Mumbai",IF(ISNUMBER(SEARCH("delhi",F9)),"Delhi-NCR",IF(ISNUMBER(SEARCH("gurgaon",F9)),"Delhi-NCR",IF(ISNUMBER(SEARCH("gurugram",F9)),"Delhi-NCR",IF(ISNUMBER(SEARCH("noida",F9)),"Delhi-NCR",IF(ISNUMBER(SEARCH("faridabad",F9)),"Delhi-NCR",IF(ISNUMBER(SEARCH("chennai",F9)),"Chennai",IF(ISNUMBER(SEARCH("hyderabad",F9)),"Hyderabad",IF(ISNUMBER(SEARCH("pune",F9)),"Pune",IF(ISNUMBER(SEARCH("kolkata",F9)),"Kolkata",IF(ISNUMBER(SEARCH("ahmedabad",F9)),"Ahmedabad",IF(ISNUMBER(SEARCH("jaipur",F9)),"Jaipur",IF(ISNUMBER(SEARCH("coimbatore",F9)),"Coimbatore",IF(ISNUMBER(SEARCH("kochi",F9)),"Kerala Cities",IF(ISNUMBER(SEARCH("cochin",F9)),"Kerala Cities",IF(ISNUMBER(SEARCH("francisco",F9)),"USA",IF(ISNUMBER(SEARCH("new york",F9)),"USA",IF(ISNUMBER(SEARCH("california",F9)),"USA",IF(ISNUMBER(SEARCH("palo alto",F9)),"USA",IF(ISNUMBER(SEARCH("santa",F9)),"USA",IF(ISNUMBER(SEARCH("singapore",F9)),"Singapore",IF(ISNUMBER(SEARCH("london",F9)),"London/UK",IF(F9="","Unknown","Other Cities"))))))))))))))))))))))))) -> Pune
A10: 9 | B10: 43805 | C10: CarDekho | D10: Ecommerce | E10: Automobile | F10: Gurgaon | G10: Ping An Global Voyager Fund | H10: =IFERROR(TRIM(LEFT(G10,FIND(",",G10)-1)),TRIM(G10)) -> Ping An Global Voyager Fund | I10: =IF(TRIM(G10)="",0,LEN(G10)-LEN(SUBSTITUTE(G10,",",""))+1) -> 1 | J10: =IF(Table1[[#This Row],[Investor Count]]>1,"Yes","No") -> No | K10: Series D | L10: 70000000 | M10: =YEAR(B10) -> 2019 | N10: =TEXT(B10,"mmmm") -> December | O10: 671.7935 | P10: =IF(ISBLANK(K10),"Unknown",IF(OR(ISNUMBER(SEARCH("seed",K10)),ISNUMBER(SEARCH("Seed",K10))),"Seed",IF(ISNUMBER(SEARCH("Series A",K10)),"Series A",IF(ISNUMBER(SEARCH("Series B",K10)),"Series B",IF(ISNUMBER(SEARCH("Series C",K10)),"Series C",IF(ISNUMBER(SEARCH("Series D",K10)),"Series D",IF(ISNUMBER(SEARCH("Private Equity",K10)),"Private Equity","Other"))))))) -> Series D | Q10: =IF(IFERROR(SEARCH("ecom",D10),0)+IFERROR(SEARCH("commerce",D10),0)+IFERROR(SEARCH("retail",D10),0)>0,"E-Commerce", IF(IFERROR(SEARCH("fintech",D10),0)+IFERROR(SEARCH("finance",D10),0)+IFERROR(SEARCH("financial",D10),0)+IFERROR(SEARCH("lending",D10),0)+IFERROR(SEARCH("payment",D10),0)+IFERROR(SEARCH("banking",D10),0)+IFERROR(SEARCH("insurance",D10),0)>0,"FinTech", IF(IFERROR(SEARCH("tech",D10),0)+IFERROR(SEARCH("software",D10),0)+IFERROR(SEARCH("saas",D10),0)+IFERROR(SEARCH("ai",D10),0)+IFERROR(SEARCH("iot",D10),0)+IFERROR(SEARCH("cloud",D10),0)+IFERROR(SEARCH("data",D10),0)+IFERROR(SEARCH("analytics",D10),0)>0,"Technology", IF(IFERROR(SEARCH("food",D10),0)+IFERROR(SEARCH("restaurant",D10),0)+IFERROR(SEARCH("hospitality",D10),0)+IFERROR(SEARCH("beverage",D10),0)+IFERROR(SEARCH("delivery",D10),0)>0,"Food & Beverage", IF(IFERROR(SEARCH("health",D10),0)+IFERROR(SEARCH("medical",D10),0)+IFERROR(SEARCH("pharma",D10),0)+IFERROR(SEARCH("wellness",D10),0)+IFERROR(SEARCH("fitness",D10),0)>0,"Healthcare", IF(IFERROR(SEARCH("edu",D10),0)+IFERROR(SEARCH("learning",D10),0)+IFERROR(SEARCH("school",D10),0)+IFERROR(SEARCH("e-tech",D10),0)>0,"Education", IF(IFERROR(SEARCH("logistics",D10),0)+IFERROR(SEARCH("transport",D10),0)+IFERROR(SEARCH("delivery",D10),0)+IFERROR(SEARCH("mobility",D10),0)+IFERROR(SEARCH("automobile",D10),0)>0,"Logistics & Transport", IF(IFERROR(SEARCH("travel",D10),0)+IFERROR(SEARCH("hotel",D10),0)+IFERROR(SEARCH("booking",D10),0)+IFERROR(SEARCH("tourism",D10),0)>0,"Travel & Hospitality", IF(IFERROR(SEARCH("fashion",D10),0)+IFERROR(SEARCH("apparel",D10),0)+IFERROR(SEARCH("clothing",D10),0)+IFERROR(SEARCH("jewelry",D10),0)+IFERROR(SEARCH("beauty",D10),0)>0,"Fashion & Lifestyle", IF(IFERROR(SEARCH("media",D10),0)+IFERROR(SEARCH("entertainment",D10),0)+IFERROR(SEARCH("video",D10),0)+IFERROR(SEARCH("gaming",D10),0)+IFERROR(SEARCH("music",D10),0)+IFERROR(SEARCH("social",D10),0)>0,"Media & Entertainment", IF(IFERROR(SEARCH("agri",D10),0)+IFERROR(SEARCH("farm",D10),0)+IFERROR(SEARCH("agtech",D10),0)>0,"Agriculture", IF(IFERROR(SEARCH("real estate",D10),0)+IFERROR(SEARCH("property",D10),0)+IFERROR(SEARCH("housing",D10),0)>0,"Real Estate", IF(IFERROR(SEARCH("energy",D10),0)+IFERROR(SEARCH("solar",D10),0)+IFERROR(SEARCH("clean tech",D10),0)+IFERROR(SEARCH("waste",D10),0)>0,"Energy & Environment", IF(IFERROR(SEARCH("hr",D10),0)+IFERROR(SEARCH("recruit",D10),0)+IFERROR(SEARCH("hiring",D10),0)+IFERROR(SEARCH("job",D10),0)>0,"HR & Recruitment", "Others")))))))))))))) -> E-Commerce | R10: =IF(ISNUMBER(SEARCH("bang",F10)),"Bangalore",IF(ISNUMBER(SEARCH("beng",F10)),"Bangalore",IF(ISNUMBER(SEARCH("mumbai",F10)),"Mumbai",IF(ISNUMBER(SEARCH("delhi",F10)),"Delhi-NCR",IF(ISNUMBER(SEARCH("gurgaon",F10)),"Delhi-NCR",IF(ISNUMBER(SEARCH("gurugram",F10)),"Delhi-NCR",IF(ISNUMBER(SEARCH("noida",F10)),"Delhi-NCR",IF(ISNUMBER(SEARCH("faridabad",F10)),"Delhi-NCR",IF(ISNUMBER(SEARCH("chennai",F10)),"Chennai",IF(ISNUMBER(SEARCH("hyderabad",F10)),"Hyderabad",IF(ISNUMBER(SEARCH("pune",F10)),"Pune",IF(ISNUMBER(SEARCH("kolkata",F10)),"Kolkata",IF(ISNUMBER(SEARCH("ahmedabad",F10)),"Ahmedabad",IF(ISNUMBER(SEARCH("jaipur",F10)),"Jaipur",IF(ISNUMBER(SEARCH("coimbatore",F10)),"Coimbatore",IF(ISNUMBER(SEARCH("kochi",F10)),"Kerala Cities",IF(ISNUMBER(SEARCH("cochin",F10)),"Kerala Cities",IF(ISNUMBER(SEARCH("francisco",F10)),"USA",IF(ISNUMBER(SEARCH("new york",F10)),"USA",IF(ISNUMBER(SEARCH("california",F10)),"USA",IF(ISNUMBER(SEARCH("palo alto",F10)),"USA",IF(ISNUMBER(SEARCH("santa",F10)),"USA",IF(ISNUMBER(SEARCH("singapore",F10)),"Singapore",IF(ISNUMBER(SEARCH("london",F10)),"London/UK",IF(F10="","Unknown","Other Cities"))))))))))))))))))))))))) -> Delhi-NCR
A11: 10 | B11: 43802 | C11: Dhruva Space | D11: Aerospace | E11: Satellite Communication | F11: Bengaluru | G11: Mumbai Angels, Ravikanth Reddy | H11: =IFERROR(TRIM(LEFT(G11,FIND(",",G11)-1)),TRIM(G11)) -> Mumbai Angels | I11: =IF(TRIM(G11)="",0,LEN(G11)-LEN(SUBSTITUTE(G11,",",""))+1) -> 2 | J11: =IF(Table1[[#This Row],[Investor Count]]>1,"Yes","No") -> Yes | K11: Seed | L11: 50000000 | M11: =YEAR(B11) -> 2019 | N11: =TEXT(B11,"mmmm") -> December | O11: 479.8525 | P11: =IF(ISBLANK(K11),"Unknown",IF(OR(ISNUMBER(SEARCH("seed",K11)),ISNUMBER(SEARCH("Seed",K11))),"Seed",IF(ISNUMBER(SEARCH("Series A",K11)),"Series A",IF(ISNUMBER(SEARCH("Series B",K11)),"Series B",IF(ISNUMBER(SEARCH("Series C",K11)),"Series C",IF(ISNUMBER(SEARCH("Series D",K11)),"Series D",IF(ISNUMBER(SEARCH("Private Equity",K11)),"Private Equity","Other"))))))) -> Seed | Q11: =IF(IFERROR(SEARCH("ecom",D11),0)+IFERROR(SEARCH("commerce",D11),0)+IFERROR(SEARCH("retail",D11),0)>0,"E-Commerce", IF(IFERROR(SEARCH("fintech",D11),0)+IFERROR(SEARCH("finance",D11),0)+IFERROR(SEARCH("financial",D11),0)+IFERROR(SEARCH("lending",D11),0)+IFERROR(SEARCH("payment",D11),0)+IFERROR(SEARCH("banking",D11),0)+IFERROR(SEARCH("insurance",D11),0)>0,"FinTech", IF(IFERROR(SEARCH("tech",D11),0)+IFERROR(SEARCH("software",D11),0)+IFERROR(SEARCH("saas",D11),0)+IFERROR(SEARCH("ai",D11),0)+IFERROR(SEARCH("iot",D11),0)+IFERROR(SEARCH("cloud",D11),0)+IFERROR(SEARCH("data",D11),0)+IFERROR(SEARCH("analytics",D11),0)>0,"Technology", IF(IFERROR(SEARCH("food",D11),0)+IFERROR(SEARCH("restaurant",D11),0)+IFERROR(SEARCH("hospitality",D11),0)+IFERROR(SEARCH("beverage",D11),0)+IFERROR(SEARCH("delivery",D11),0)>0,"Food & Beverage", IF(IFERROR(SEARCH("health",D11),0)+IFERROR(SEARCH("medical",D11),0)+IFERROR(SEARCH("pharma",D11),0)+IFERROR(SEARCH("wellness",D11),0)+IFERROR(SEARCH("fitness",D11),0)>0,"Healthcare", IF(IFERROR(SEARCH("edu",D11),0)+IFERROR(SEARCH("learning",D11),0)+IFERROR(SEARCH("school",D11),0)+IFERROR(SEARCH("e-tech",D11),0)>0,"Education", IF(IFERROR(SEARCH("logistics",D11),0)+IFERROR(SEARCH("transport",D11),0)+IFERROR(SEARCH("delivery",D11),0)+IFERROR(SEARCH("mobility",D11),0)+IFERROR(SEARCH("automobile",D11),0)>0,"Logistics & Transport", IF(IFERROR(SEARCH("travel",D11),0)+IFERROR(SEARCH("hotel",D11),0)+IFERROR(SEARCH("booking",D11),0)+IFERROR(SEARCH("tourism",D11),0)>0,"Travel & Hospitality", IF(IFERROR(SEARCH("fashion",D11),0)+IFERROR(SEARCH("apparel",D11),0)+IFERROR(SEARCH("clothing",D11),0)+IFERROR(SEARCH("jewelry",D11),0)+IFERROR(SEARCH("beauty",D11),0)>0,"Fashion & Lifestyle", IF(IFERROR(SEARCH("media",D11),0)+IFERROR(SEARCH("entertainment",D11),0)+IFERROR(SEARCH("video",D11),0)+IFERROR(SEARCH("gaming",D11),0)+IFERROR(SEARCH("music",D11),0)+IFERROR(SEARCH("social",D11),0)>0,"Media & Entertainment", IF(IFERROR(SEARCH("agri",D11),0)+IFERROR(SEARCH("farm",D11),0)+IFERROR(SEARCH("agtech",D11),0)>0,"Agriculture", IF(IFERROR(SEARCH("real estate",D11),0)+IFERROR(SEARCH("property",D11),0)+IFERROR(SEARCH("housing",D11),0)>0,"Real Estate", IF(IFERROR(SEARCH("energy",D11),0)+IFERROR(SEARCH("solar",D11),0)+IFERROR(SEARCH("clean tech",D11),0)+IFERROR(SEARCH("waste",D11),0)>0,"Energy & Environment", IF(IFERROR(SEARCH("hr",D11),0)+IFERROR(SEARCH("recruit",D11),0)+IFERROR(SEARCH("hiring",D11),0)+IFERROR(SEARCH("job",D11),0)>0,"HR & Recruitment", "Others")))))))))))))) -> Others | R11: =IF(ISNUMBER(SEARCH("bang",F11)),"Bangalore",IF(ISNUMBER(SEARCH("beng",F11)),"Bangalore",IF(ISNUMBER(SEARCH("mumbai",F11)),"Mumbai",IF(ISNUMBER(SEARCH("delhi",F11)),"Delhi-NCR",IF(ISNUMBER(SEARCH("gurgaon",F11)),"Delhi-NCR",IF(ISNUMBER(SEARCH("gurugram",F11)),"Delhi-NCR",IF(ISNUMBER(SEARCH("noida",F11)),"Delhi-NCR",IF(ISNUMBER(SEARCH("faridabad",F11)),"Delhi-NCR",IF(ISNUMBER(SEARCH("chennai",F11)),"Chennai",IF(ISNUMBER(SEARCH("hyderabad",F11)),"Hyderabad",IF(ISNUMBER(SEARCH("pune",F11)),"Pune",IF(ISNUMBER(SEARCH("kolkata",F11)),"Kolkata",IF(ISNUMBER(SEARCH("ahmedabad",F11)),"Ahmedabad",IF(ISNUMBER(SEARCH("jaipur",F11)),"Jaipur",IF(ISNUMBER(SEARCH("coimbatore",F11)),"Coimbatore",IF(ISNUMBER(SEARCH("kochi",F11)),"Kerala Cities",IF(ISNUMBER(SEARCH("cochin",F11)),"Kerala Cities",IF(ISNUMBER(SEARCH("francisco",F11)),"USA",IF(ISNUMBER(SEARCH("new york",F11)),"USA",IF(ISNUMBER(SEARCH("california",F11)),"USA",IF(ISNUMBER(SEARCH("palo alto",F11)),"USA",IF(ISNUMBER(SEARCH("santa",F11)),"USA",IF(ISNUMBER(SEARCH("singapore",F11)),"Singapore",IF(ISNUMBER(SEARCH("london",F11)),"London/UK",IF(F11="","Unknown","Other Cities"))))))))))))))))))))))))) -> Bangalore
A12: 11 | B12: 43812 | C12: Rivigo | D12: Technology | E12: Logistics Services , Solutions | F12: Gurgaon | G12: Saif Partners, Spring Canter Investment Ltd | H12: =IFERROR(TRIM(LEFT(G12,FIND(",",G12)-1)),TRIM(G12)) -> Saif Partners | I12: =IF(TRIM(G12)="",0,LEN(G12)-LEN(SUBSTITUTE(G12,",",""))+1) -> 2 | J12: =IF(Table1[[#This Row],[Investor Count]]>1,"Yes","No") -> Yes | K12: Series F | L12: 20000000 | M12: =YEAR(B12) -> 2019 | N12: =TEXT(B12,"mmmm") -> December | O12: 191.941 | P12: =IF(ISBLANK(K12),"Unknown",IF(OR(ISNUMBER(SEARCH("seed",K12)),ISNUMBER(SEARCH("Seed",K12))),"Seed",IF(ISNUMBER(SEARCH("Series A",K12)),"Series A",IF(ISNUMBER(SEARCH("Series B",K12)),"Series B",IF(ISNUMBER(SEARCH("Series C",K12)),"Series C",IF(ISNUMBER(SEARCH("Series D",K12)),"Series D",IF(ISNUMBER(SEARCH("Private Equity",K12)),"Private Equity","Other"))))))) -> Other | Q12: =IF(IFERROR(SEARCH("ecom",D12),0)+IFERROR(SEARCH("commerce",D12),0)+IFERROR(SEARCH("retail",D12),0)>0,"E-Commerce", IF(IFERROR(SEARCH("fintech",D12),0)+IFERROR(SEARCH("finance",D12),0)+IFERROR(SEARCH("financial",D12),0)+IFERROR(SEARCH("lending",D12),0)+IFERROR(SEARCH("payment",D12),0)+IFERROR(SEARCH("banking",D12),0)+IFERROR(SEARCH("insurance",D12),0)>0,"FinTech", IF(IFERROR(SEARCH("tech",D12),0)+IFERROR(SEARCH("software",D12),0)+IFERROR(SEARCH("saas",D12),0)+IFERROR(SEARCH("ai",D12),0)+IFERROR(SEARCH("iot",D12),0)+IFERROR(SEARCH("cloud",D12),0)+IFERROR(SEARCH("data",D12),0)+IFERROR(SEARCH("analytics",D12),0)>0,"Technology", IF(IFERROR(SEARCH("food",D12),0)+IFERROR(SEARCH("restaurant",D12),0)+IFERROR(SEARCH("hospitality",D12),0)+IFERROR(SEARCH("beverage",D12),0)+IFERROR(SEARCH("delivery",D12),0)>0,"Food & Beverage", IF(IFERROR(SEARCH("health",D12),0)+IFERROR(SEARCH("medical",D12),0)+IFERROR(SEARCH("pharma",D12),0)+IFERROR(SEARCH("wellness",D12),0)+IFERROR(SEARCH("fitness",D12),0)>0,"Healthcare", IF(IFERROR(SEARCH("edu",D12),0)+IFERROR(SEARCH("learning",D12),0)+IFERROR(SEARCH("school",D12),0)+IFERROR(SEARCH("e-tech",D12),0)>0,"Education", IF(IFERROR(SEARCH("logistics",D12),0)+IFERROR(SEARCH("transport",D12),0)+IFERROR(SEARCH("delivery",D12),0)+IFERROR(SEARCH("mobility",D12),0)+IFERROR(SEARCH("automobile",D12),0)>0,"Logistics & Transport", IF(IFERROR(SEARCH("travel",D12),0)+IFERROR(SEARCH("hotel",D12),0)+IFERROR(SEARCH("booking",D12),0)+IFERROR(SEARCH("tourism",D12),0)>0,"Travel & Hospitality", IF(IFERROR(SEARCH("fashion",D12),0)+IFERROR(SEARCH("apparel",D12),0)+IFERROR(SEARCH("clothing",D12),0)+IFERROR(SEARCH("jewelry",D12),0)+IFERROR(SEARCH("beauty",D12),0)>0,"Fashion & Lifestyle", IF(IFERROR(SEARCH("media",D12),0)+IFERROR(SEARCH("entertainment",D12),0)+IFERROR(SEARCH("video",D12),0)+IFERROR(SEARCH("gaming",D12),0)+IFERROR(SEARCH("music",D12),0)+IFERROR(SEARCH("social",D12),0)>0,"Media & Entertainment", IF(IFERROR(SEARCH("agri",D12),0)+IFERROR(SEARCH("farm",D12),0)+IFERROR(SEARCH("agtech",D12),0)>0,"Agriculture", IF(IFERROR(SEARCH("real estate",D12),0)+IFERROR(SEARCH("property",D12),0)+IFERROR(SEARCH("housing",D12),0)>0,"Real Estate", IF(IFERROR(SEARCH("energy",D12),0)+IFERROR(SEARCH("solar",D12),0)+IFERROR(SEARCH("clean tech",D12),0)+IFERROR(SEARCH("waste",D12),0)>0,"Energy & Environment", IF(IFERROR(SEARCH("hr",D12),0)+IFERROR(SEARCH("recruit",D12),0)+IFERROR(SEARCH("hiring",D12),0)+IFERROR(SEARCH("job",D12),0)>0,"HR & Recruitment", "Others")))))))))))))) -> Technology | R12: =IF(ISNUMBER(SEARCH("bang",F12)),"Bangalore",IF(ISNUMBER(SEARCH("beng",F12)),"Bangalore",IF(ISNUMBER(SEARCH("mumbai",F12)),"Mumbai",IF(ISNUMBER(SEARCH("delhi",F12)),"Delhi-NCR",IF(ISNUMBER(SEARCH("gurgaon",F12)),"Delhi-NCR",IF(ISNUMBER(SEARCH("gurugram",F12)),"Delhi-NCR",IF(ISNUMBER(SEARCH("noida",F12)),"Delhi-NCR",IF(ISNUMBER(SEARCH("faridabad",F12)),"Delhi-NCR",IF(ISNUMBER(SEARCH("chennai",F12)),"Chennai",IF(ISNUMBER(SEARCH("hyderabad",F12)),"Hyderabad",IF(ISNUMBER(SEARCH("pune",F12)),"Pune",IF(ISNUMBER(SEARCH("kolkata",F12)),"Kolkata",IF(ISNUMBER(SEARCH("ahmedabad",F12)),"Ahmedabad",IF(ISNUMBER(SEARCH("jaipur",F12)),"Jaipur",IF(ISNUMBER(SEARCH("coimbatore",F12)),"Coimbatore",IF(ISNUMBER(SEARCH("kochi",F12)),"Kerala Cities",IF(ISNUMBER(SEARCH("cochin",F12)),"Kerala Cities",IF(ISNUMBER(SEARCH("francisco",F12)),"USA",IF(ISNUMBER(SEARCH("new york",F12)),"USA",IF(ISNUMBER(SEARCH("california",F12)),"USA",IF(ISNUMBER(SEARCH("palo alto",F12)),"USA",IF(ISNUMBER(SEARCH("santa",F12)),"USA",IF(ISNUMBER(SEARCH("singapore",F12)),"Singapore",IF(ISNUMBER(SEARCH("london",F12)),"London/UK",IF(F12="","Unknown","Other Cities"))))))))))))))))))))))))) -> Delhi-NCR
